Processing queries:   0%|          | 0/99 [00:00<?, ?problem/s]Processing queries:   0%|          | 0/99 [00:05<?, ?problem/s]
Traceback (most recent call last):
  File "/home/ubuntu/MedAgents-2/main.py", line 131, in <module>
    for future in tqdm(as_completed(future_to_index),
  File "/home/ubuntu/venv/lib/python3.12/site-packages/tqdm/std.py", line 1181, in __iter__
    for obj in iterable:
  File "/usr/lib/python3.12/concurrent/futures/_base.py", line 243, in as_completed
    waiter.event.wait(wait_timeout)
  File "/usr/lib/python3.12/threading.py", line 655, in wait
    signaled = self._cond.wait(timeout)
               ^^^^^^^^^^^^^^^^^^^^^^^^
  File "/usr/lib/python3.12/threading.py", line 355, in wait
    waiter.acquire()
KeyboardInterrupt

During handling of the above exception, another exception occurred:

Traceback (most recent call last):
  File "/home/ubuntu/MedAgents-2/main.py", line 126, in <module>
    with ThreadPoolExecutor(max_workers=args.num_processes) as executor:
  File "/usr/lib/python3.12/concurrent/futures/_base.py", line 647, in __exit__
    self.shutdown(wait=True)
  File "/usr/lib/python3.12/concurrent/futures/thread.py", line 238, in shutdown
    t.join()
  File "/usr/lib/python3.12/threading.py", line 1147, in join
    self._wait_for_tstate_lock()
  File "/usr/lib/python3.12/threading.py", line 1167, in _wait_for_tstate_lock
    if lock.acquire(block, timeout):
       ^^^^^^^^^^^^^^^^^^^^^^^^^^^^
KeyboardInterrupt
